<?xml version="1.0"?>
<robot name="rafyu6dof">

  <material name="blue">
    <color rgba="0 0 0.8 1"/>
  </material>
  <material name="grey">
    <color rgba="0.5 0.5 0.5 1"/>
  </material>
  <material name="white">
    <color rgba="1 1 1 1"/>
  </material>

      
  <link name="base_link">
    <visual>
      <geometry>
        <box size="1 1 1"/>
      </geometry>
      <origin rpy="0 0 0" xyz="0 0 0"/>
      <material name="blue"/>
    </visual>
  </link>
  
    <link name="shoulder1">
    <visual>
     <geometry>
        <mesh  filename="package://rafyu6dof/meshes/shoulder1.STL" scale="0.01 0.01 0.01"/>
      </geometry>
      <origin rpy="1.571 0 1.571" xyz="-0.5 -0.5 -0.05"/>
      <material name="grey"/>
    </visual>
  </link>
  
 <link name="shoulder2">
    <visual>
     <geometry>
        <mesh  filename="package://rafyu6dof/meshes/shoulder2.STL" scale="0.01 0.01 0.01"/>
      </geometry>
      <origin rpy="1.571 0 1.571" xyz="-0.5 -0.352 -0.05"/>
      <material name="grey"/>
    </visual>
  </link>
  
    <joint name="shoulder1_to_shoulder2" type="fixed">
     <axis xyz="0 0 1"/>
    <parent link="shoulder1"/>
    <child link="shoulder2"/>
    <origin xyz="0 0 0"/>
  </joint>
  
  <joint name="base_to_shoulder" type="revolute">
     <axis xyz="0 0 1"/>
    <limit effort="1000.0" lower="-1.571" upper="1.571" velocity="0.5"/>
    <parent link="base_link"/>
    <child link="shoulder1"/>
    <origin xyz="0 0 0.55"/>
  </joint>
  
  <link name="lower_arm">
    <visual>
     <geometry>
        <mesh  filename="package://rafyu6dof/meshes/lower_arm.STL" scale="0.01 0.01 0.01"/>
      </geometry>
      <origin rpy="1.571 0 0" xyz="-0.35 -0.25 -0.33"/>
      <material name="white"/>
    </visual>
  </link>

  <joint name="shoulder1_to_lower_arm" type="revolute">
     <axis xyz="0 1 0"/>
    <limit effort="1000.0" lower="0.0" upper="1.571" velocity="0.5"/>
    <parent link="shoulder1"/>
    <child link="lower_arm"/>
    <origin xyz="0 0 0.45"/>
  </joint>
  
  <link name="upper_arm">
    <visual>
      <geometry>
        <mesh  filename="package://rafyu6dof/meshes/upper_arm.STL" scale="0.01 0.01 0.01"/>
      </geometry>
      <origin rpy="1.571 0 0" xyz="-0.9 0.33 -0.4"/>
      <material name="grey"/>
    </visual>
  </link>
  
  <joint name="lower_arm_to_upper_arm" type="revolute">
     <axis xyz="0 1 0"/>
    <limit effort="1000.0" lower="-1.571" upper="1.00" velocity="0.5"/>
    <parent link="lower_arm"/>
    <child link="upper_arm"/>
    <origin xyz="0 0 1.8"/>
  </joint>

  <link name="wrist">
    <visual>
      <geometry>
        <mesh  filename="package://rafyu6dof/meshes/wrist.STL" scale="0.01 0.01 0.01"/>
      </geometry>
      <origin rpy="0 0 -1.571" xyz="0 0.37 -0.2"/>
      <material name="white"/>
    </visual>
  </link>
  
  <joint name="upper_arm_to_wrist" type="revolute">
     <axis xyz="1 0 0"/>
    <limit effort="1000.0" lower="-1.571" upper="1.571" velocity="0.5"/>
    <parent link="upper_arm"/>
    <child link="wrist"/>
    <origin xyz="1 0.01 0.34"/>
  </joint>
  
    <link name="hand">
    <visual>
      <geometry>
        <mesh  filename="package://rafyu6dof/meshes/hand.STL" scale="0.01 0.01 0.01"/>
      </geometry>
      <origin rpy="0 0 -1.571" xyz="-0.15 0.23 -0.2"/>
      <material name="grey"/>
    </visual>
  </link>
  
  <joint name="wrist_to_hand" type="revolute">
     <axis xyz="0 1 0"/>
    <limit effort="1000.0" lower="-1.571" upper="1.571" velocity="0.5"/>
    <parent link="wrist"/>
    <child link="hand"/>
    <origin xyz="1.15 0 0"/>
  </joint>
  
    <link name="hand_rotate">
    <visual>
      <geometry>
        <cylinder length="0.1" radius="0.1"/>
      </geometry>
      <origin rpy="0 1.571 0" xyz="0 0 0"/>
      <material name="white"/>
    </visual>
  </link>
  
  <joint name="hand_to_hand_rotate" type="revolute">
     <axis xyz="1 0 0"/>
    <limit effort="1000.0" lower="-1.571" upper="1.571" velocity="0.5"/>
    <parent link="hand"/>
    <child link="hand_rotate"/>
    <origin xyz="0.3 0 0"/>
  </joint>
  
   <link name="grip_1">
    <visual>
      <geometry>
        <cylinder length="0.1" radius="0.02"/>
      </geometry>
      <origin rpy="0 1.571 0" xyz="0 -0.05 -0.1"/>
      <material name="blue"/>
    </visual>
  </link>
  
   <link name="grip_2">
    <visual>
      <geometry>
        <cylinder length="0.1" radius="0.02"/>
      </geometry>
      <origin rpy="0 1.571 0" xyz="0.2 0.05 -0.1"/>
      <material name="blue"/>
    </visual>
  </link>
  
  <joint name="grip_1_extension" type="prismatic">
    <parent link="hand_rotate"/>
    <child link="grip_1"/>
    <limit effort="1000.0" lower="-0.04" upper="0.02" velocity="0.5"/>
    <origin rpy="0 0 0" xyz="0.1 0 0.1"/>
  </joint>
  
  <joint name="grip_2_extension" type="prismatic">
    <parent link="hand_rotate"/>
    <child link="grip_2"/>
    <limit effort="1000.0" lower="-0.02" upper="0.04" velocity="0.5"/>
    <origin rpy="0 0 0" xyz="-0.1 0 0.1"/>
  </joint>
  
  
</robot>
